Workbook

Sheet PLANO DE SAÚDE
B2: TIPO DE DESP: | F2: =SUM(F4:F211) -> 291294.1 | M2: TOTAL | O2: CONTA | P2: 31201005 | Q2: 31201003
A3: EST | B3: NOME | C3: CCUSTO | D3: DATA | E3: Nº DOC | F3: MENSAL | G3: EXAME | H3: DESCON | I3: REPRES | J3: INSCRI | M3: =SUM(M4:M211) -> 291294.1
A4: 101 | B4: UNIMED ITUVERAVA | C4: 13021 | E4: UNIMED ITUVERAVA | F4: 546.96 | K4: ="|"&"PAGTO DOC - "&E4&"|"&"PLANO DE SAUDE - "&B4&"|"&"C CUSTO - "&LEFT(C4,5)&"|"&"TOTAL: "&F4&"|" -> |PAGTO DOC - UNIMED ITUVERAVA|PLANO DE SAUDE - UNIMED ITUVERAVA|C CUSTO - 13021|TOTAL: 546,96| | M4: =SUM(F4:L4) -> 546.96 | N4: ="|"&"PAGTO DOC - "&F4&"|"&"DESP - "&B4&"|"&"CENTRO CUSTO - "&C4&"|"&I4&"|"&G4&"|"&#REF!&"|"&J4&"|"&H4&"|"&K4&"|"&L4&"|" -> #REF! | O4: =IF(M4=0,0,IF(E4="SEGURO DE VIDA EM GRUPO","31201003","31201005")) -> 31201005
A5: 101 | B5: UNIMED ITUVERAVA | C5: 14051 | E5: UNIMED ITUVERAVA | F5: 2161.26 | K5: ="|"&"PAGTO DOC - "&E5&"|"&"PLANO DE SAUDE - "&B5&"|"&"C CUSTO - "&LEFT(C5,5)&"|"&"TOTAL: "&F5&"|" -> |PAGTO DOC - UNIMED ITUVERAVA|PLANO DE SAUDE - UNIMED ITUVERAVA|C CUSTO - 14051|TOTAL: 2161,26| | M5: =SUM(F5:L5) -> 2161.26 | N5: ="|"&"PAGTO DOC - "&F5&"|"&"DESP - "&B5&"|"&"CENTRO CUSTO - "&C5&"|"&I5&"|"&G5&"|"&#REF!&"|"&J5&"|"&H5&"|"&K5&"|"&L5&"|" -> #REF! | O5: =IF(M5=0,0,IF(E5="SEGURO DE VIDA EM GRUPO","31201003","31201005")) -> 31201005
A6: 101 | B6: UNIMED ITUVERAVA | C6: 14058 | E6: UNIMED ITUVERAVA | F6: 2014.32 | K6: ="|"&"PAGTO DOC - "&E6&"|"&"PLANO DE SAUDE - "&B6&"|"&"C CUSTO - "&LEFT(C6,5)&"|"&"TOTAL: "&F6&"|" -> |PAGTO DOC - UNIMED ITUVERAVA|PLANO DE SAUDE - UNIMED ITUVERAVA|C CUSTO - 14058|TOTAL: 2014,32| | M6: =SUM(F6:L6) -> 2014.32 | N6: ="|"&"PAGTO DOC - "&F6&"|"&"DESP - "&B6&"|"&"CENTRO CUSTO - "&C6&"|"&I6&"|"&G6&"|"&#REF!&"|"&J6&"|"&H6&"|"&K6&"|"&L6&"|" -> #REF! | O6: =IF(M6=0,0,IF(E6="SEGURO DE VIDA EM GRUPO","31201003","31201005")) -> 31201005
A7: 101 | B7: UNIMED ITUVERAVA | C7: 31060 | E7: UNIMED ITUVERAVA | F7: 546.96 | K7: ="|"&"PAGTO DOC - "&E7&"|"&"PLANO DE SAUDE - "&B7&"|"&"C CUSTO - "&LEFT(C7,5)&"|"&"TOTAL: "&F7&"|" -> |PAGTO DOC - UNIMED ITUVERAVA|PLANO DE SAUDE - UNIMED ITUVERAVA|C CUSTO - 31060|TOTAL: 546,96| | M7: =SUM(F7:L7) -> 546.96 | N7: ="|"&"PAGTO DOC - "&F7&"|"&"DESP - "&B7&"|"&"CENTRO CUSTO - "&C7&"|"&I7&"|"&G7&"|"&#REF!&"|"&J7&"|"&H7&"|"&K7&"|"&L7&"|" -> #REF! | O7: =IF(M7=0,0,IF(E7="SEGURO DE VIDA EM GRUPO","31201003","31201005")) -> 31201005
A8: 101 | B8: UNIMED ITUVERAVA | C8: 31070 | E8: UNIMED ITUVERAVA | F8: 546.96 | K8: ="|"&"PAGTO DOC - "&E8&"|"&"PLANO DE SAUDE - "&B8&"|"&"C CUSTO - "&LEFT(C8,5)&"|"&"TOTAL: "&F8&"|" -> |PAGTO DOC - UNIMED ITUVERAVA|PLANO DE SAUDE - UNIMED ITUVERAVA|C CUSTO - 31070|TOTAL: 546,96| | M8: =SUM(F8:L8) -> 546.96 | N8: ="|"&"PAGTO DOC - "&F8&"|"&"DESP - "&B8&"|"&"CENTRO CUSTO - "&C8&"|"&I8&"|"&G8&"|"&#REF!&"|"&J8&"|"&H8&"|"&K8&"|"&L8&"|" -> #REF! | O8: =IF(M8=0,0,IF(E8="SEGURO DE VIDA EM GRUPO","31201003","31201005")) -> 31201005
A9: 101 | B9: UNIMED ITUVERAVA | C9: 31114 | E9: UNIMED ITUVERAVA | F9: 2417.14 | K9: ="|"&"PAGTO DOC - "&E9&"|"&"PLANO DE SAUDE - "&B9&"|"&"C CUSTO - "&LEFT(C9,5)&"|"&"TOTAL: "&F9&"|" -> |PAGTO DOC - UNIMED ITUVERAVA|PLANO DE SAUDE - UNIMED ITUVERAVA|C CUSTO - 31114|TOTAL: 2417,14| | M9: =SUM(F9:L9) -> 2417.14 | N9: ="|"&"PAGTO DOC - "&F9&"|"&"DESP - "&B9&"|"&"CENTRO CUSTO - "&C9&"|"&I9&"|"&G9&"|"&#REF!&"|"&J9&"|"&H9&"|"&K9&"|"&L9&"|" -> #REF! | O9: =IF(M9=0,0,IF(E9="SEGURO DE VIDA EM GRUPO","31201003","31201005")) -> 31201005
A10: 101 | B10: UNIMED ITUVERAVA | C10: 11012 | E10: UNIMED ITUVERAVA | F10: 1093.92 | K10: ="|"&"PAGTO DOC - "&E10&"|"&"PLANO DE SAUDE - "&B10&"|"&"C CUSTO - "&LEFT(C10,5)&"|"&"TOTAL: "&F10&"|" -> |PAGTO DOC - UNIMED ITUVERAVA|PLANO DE SAUDE - UNIMED ITUVERAVA|C CUSTO - 11012|TOTAL: 1093,92| | M10: =SUM(F10:L10) -> 1093.92 | N10: ="|"&"PAGTO DOC - "&F10&"|"&"DESP - "&B10&"|"&"CENTRO CUSTO - "&C10&"|"&I10&"|"&G10&"|"&#REF!&"|"&J10&"|"&H10&"|"&K10&"|"&L10&"|" -> #REF! | O10: =IF(M10=0,0,IF(E10="SEGURO DE VIDA EM GRUPO","31201003","31201005")) -> 31201005
A11: 101 | B11: UNIMED ITUVERAVA | C11: 13011 | E11: UNIMED ITUVERAVA | F11: 1323.22 | K11: ="|"&"PAGTO DOC - "&E11&"|"&"PLANO DE SAUDE - "&B11&"|"&"C CUSTO - "&LEFT(C11,5)&"|"&"TOTAL: "&F11&"|" -> |PAGTO DOC - UNIMED ITUVERAVA|PLANO DE SAUDE - UNIMED ITUVERAVA|C CUSTO - 13011|TOTAL: 1323,22| | M11: =SUM(F11:L11) -> 1323.22 | N11: ="|"&"PAGTO DOC - "&F11&"|"&"DESP - "&B11&"|"&"CENTRO CUSTO - "&C11&"|"&I11&"|"&G11&"|"&#REF!&"|"&J11&"|"&H11&"|"&K11&"|"&L11&"|" -> #REF! | O11: =IF(M11=0,0,IF(E11="SEGURO DE VIDA EM GRUPO","31201003","31201005")) -> 31201005
A12: 101 | B12: UNIMED ITUVERAVA | C12: 13012 | E12: UNIMED ITUVERAVA | F12: 1005.56 | K12: ="|"&"PAGTO DOC - "&E12&"|"&"PLANO DE SAUDE - "&B12&"|"&"C CUSTO - "&LEFT(C12,5)&"|"&"TOTAL: "&F12&"|" -> |PAGTO DOC - UNIMED ITUVERAVA|PLANO DE SAUDE - UNIMED ITUVERAVA|C CUSTO - 13012|TOTAL: 1005,56| | M12: =SUM(F12:L12) -> 1005.56 | N12: ="|"&"PAGTO DOC - "&F12&"|"&"DESP - "&B12&"|"&"CENTRO CUSTO - "&C12&"|"&I12&"|"&G12&"|"&#REF!&"|"&J12&"|"&H12&"|"&K12&"|"&L12&"|" -> #REF! | O12: =IF(M12=0,0,IF(E12="SEGURO DE VIDA EM GRUPO","31201003","31201005")) -> 31201005
A13: 101 | B13: UNIMED ITUVERAVA | C13: 13013 | E13: UNIMED ITUVERAVA | F13: 8067.44 | K13: ="|"&"PAGTO DOC - "&E13&"|"&"PLANO DE SAUDE - "&B13&"|"&"C CUSTO - "&LEFT(C13,5)&"|"&"TOTAL: "&F13&"|" -> |PAGTO DOC - UNIMED ITUVERAVA|PLANO DE SAUDE - UNIMED ITUVERAVA|C CUSTO - 13013|TOTAL: 8067,44| | M13: =SUM(F13:L13) -> 8067.44 | N13: ="|"&"PAGTO DOC - "&F13&"|"&"DESP - "&B13&"|"&"CENTRO CUSTO - "&C13&"|"&I13&"|"&G13&"|"&#REF!&"|"&J13&"|"&H13&"|"&K13&"|"&L13&"|" -> #REF! | O13: =IF(M13=0,0,IF(E13="SEGURO DE VIDA EM GRUPO","31201003","31201005")) -> 31201005
A14: 101 | B14: UNIMED ITUVERAVA | C14: 13014 | E14: UNIMED ITUVERAVA | F14: 2187.84 | K14: ="|"&"PAGTO DOC - "&E14&"|"&"PLANO DE SAUDE - "&B14&"|"&"C CUSTO - "&LEFT(C14,5)&"|"&"TOTAL: "&F14&"|" -> |PAGTO DOC - UNIMED ITUVERAVA|PLANO DE SAUDE - UNIMED ITUVERAVA|C CUSTO - 13014|TOTAL: 2187,84| | M14: =SUM(F14:L14) -> 2187.84 | N14: ="|"&"PAGTO DOC - "&F14&"|"&"DESP - "&B14&"|"&"CENTRO CUSTO - "&C14&"|"&I14&"|"&G14&"|"&#REF!&"|"&J14&"|"&H14&"|"&K14&"|"&L14&"|" -> #REF! | O14: =IF(M14=0,0,IF(E14="SEGURO DE VIDA EM GRUPO","31201003","31201005")) -> 31201005
A15: 101 | B15: UNIMED ITUVERAVA | C15: 13016 | E15: UNIMED ITUVERAVA | F15: 1464.16 | K15: ="|"&"PAGTO DOC - "&E15&"|"&"PLANO DE SAUDE - "&B15&"|"&"C CUSTO - "&LEFT(C15,5)&"|"&"TOTAL: "&F15&"|" -> |PAGTO DOC - UNIMED ITUVERAVA|PLANO DE SAUDE - UNIMED ITUVERAVA|C CUSTO - 13016|TOTAL: 1464,16| | M15: =SUM(F15:L15) -> 1464.16 | N15: ="|"&"PAGTO DOC - "&F15&"|"&"DESP - "&B15&"|"&"CENTRO CUSTO - "&C15&"|"&I15&"|"&G15&"|"&#REF!&"|"&J15&"|"&H15&"|"&K15&"|"&L15&"|" -> #REF! | O15: =IF(M15=0,0,IF(E15="SEGURO DE VIDA EM GRUPO","31201003","31201005")) -> 31201005
A16: 101 | B16: UNIMED ITUVERAVA | C16: 13017 | E16: UNIMED ITUVERAVA | F16: 1640.88 | K16: ="|"&"PAGTO DOC - "&E16&"|"&"PLANO DE SAUDE - "&B16&"|"&"C CUSTO - "&LEFT(C16,5)&"|"&"TOTAL: "&F16&"|" -> |PAGTO DOC - UNIMED ITUVERAVA|PLANO DE SAUDE - UNIMED ITUVERAVA|C CUSTO - 13017|TOTAL: 1640,88| | M16: =SUM(F16:L16) -> 1640.88 | N16: ="|"&"PAGTO DOC - "&F16&"|"&"DESP - "&B16&"|"&"CENTRO CUSTO - "&C16&"|"&I16&"|"&G16&"|"&#REF!&"|"&J16&"|"&H16&"|"&K16&"|"&L16&"|" -> #REF! | O16: =IF(M16=0,0,IF(E16="SEGURO DE VIDA EM GRUPO","31201003","31201005")) -> 31201005
A17: 101 | B17: UNIMED ITUVERAVA | C17: 13018 | E17: UNIMED ITUVERAVA | F17: 1005.56 | K17: ="|"&"PAGTO DOC - "&E17&"|"&"PLANO DE SAUDE - "&B17&"|"&"C CUSTO - "&LEFT(C17,5)&"|"&"TOTAL: "&F17&"|" -> |PAGTO DOC - UNIMED ITUVERAVA|PLANO DE SAUDE - UNIMED ITUVERAVA|C CUSTO - 13018|TOTAL: 1005,56| | M17: =SUM(F17:L17) -> 1005.56 | N17: ="|"&"PAGTO DOC - "&F17&"|"&"DESP - "&B17&"|"&"CENTRO CUSTO - "&C17&"|"&I17&"|"&G17&"|"&#REF!&"|"&J17&"|"&H17&"|"&K17&"|"&L17&"|" -> #REF! | O17: =IF(M17=0,0,IF(E17="SEGURO DE VIDA EM GRUPO","31201003","31201005")) -> 31201005
A18: 101 | B18: UNIMED ITUVERAVA | C18: 13019 | E18: UNIMED ITUVERAVA | F18: 776.26 | K18: ="|"&"PAGTO DOC - "&E18&"|"&"PLANO DE SAUDE - "&B18&"|"&"C CUSTO - "&LEFT(C18,5)&"|"&"TOTAL: "&F18&"|" -> |PAGTO DOC - UNIMED ITUVERAVA|PLANO DE SAUDE - UNIMED ITUVERAVA|C CUSTO - 13019|TOTAL: 776,26| | M18: =SUM(F18:L18) -> 776.26 | N18: ="|"&"PAGTO DOC - "&F18&"|"&"DESP - "&B18&"|"&"CENTRO CUSTO - "&C18&"|"&I18&"|"&G18&"|"&#REF!&"|"&J18&"|"&H18&"|"&K18&"|"&L18&"|" -> #REF! | O18: =IF(M18=0,0,IF(E18="SEGURO DE VIDA EM GRUPO","31201003","31201005")) -> 31201005
A19: 101 | B19: UNIMED ITUVERAVA | C19: 13021 | E19: UNIMED ITUVERAVA | F19: 2646.44 | K19: ="|"&"PAGTO DOC - "&E19&"|"&"PLANO DE SAUDE - "&B19&"|"&"C CUSTO - "&LEFT(C19,5)&"|"&"TOTAL: "&F19&"|" -> |PAGTO DOC - UNIMED ITUVERAVA|PLANO DE SAUDE - UNIMED ITUVERAVA|C CUSTO - 13021|TOTAL: 2646,44| | M19: =SUM(F19:L19) -> 2646.44 | N19: ="|"&"PAGTO DOC - "&F19&"|"&"DESP - "&B19&"|"&"CENTRO CUSTO - "&C19&"|"&I19&"|"&G19&"|"&#REF!&"|"&J19&"|"&H19&"|"&K19&"|"&L19&"|" -> #REF! | O19: =IF(M19=0,0,IF(E19="SEGURO DE VIDA EM GRUPO","31201003","31201005")) -> 31201005
A20: 101 | B20: UNIMED ITUVERAVA | C20: 14012 | E20: UNIMED ITUVERAVA | F20: 1870.18 | K20: ="|"&"PAGTO DOC - "&E20&"|"&"PLANO DE SAUDE - "&B20&"|"&"C CUSTO - "&LEFT(C20,5)&"|"&"TOTAL: "&F20&"|" -> |PAGTO DOC - UNIMED ITUVERAVA|PLANO DE SAUDE - UNIMED ITUVERAVA|C CUSTO - 14012|TOTAL: 1870,18| | M20: =SUM(F20:L20) -> 1870.18 | N20: ="|"&"PAGTO DOC - "&F20&"|"&"DESP - "&B20&"|"&"CENTRO CUSTO - "&C20&"|"&I20&"|"&G20&"|"&#REF!&"|"&J20&"|"&H20&"|"&K20&"|"&L20&"|" -> #REF! | O20: =IF(M20=0,0,IF(E20="SEGURO DE VIDA EM GRUPO","31201003","31201005")) -> 31201005
A21: 101 | B21: UNIMED ITUVERAVA | C21: 14051 | E21: UNIMED ITUVERAVA | F21: 2707.02 | K21: ="|"&"PAGTO DOC - "&E21&"|"&"PLANO DE SAUDE - "&B21&"|"&"C CUSTO - "&LEFT(C21,5)&"|"&"TOTAL: "&F21&"|" -> |PAGTO DOC - UNIMED ITUVERAVA|PLANO DE SAUDE - UNIMED ITUVERAVA|C CUSTO - 14051|TOTAL: 2707,02| | M21: =SUM(F21:L21) -> 2707.02 | N21: ="|"&"PAGTO DOC - "&F21&"|"&"DESP - "&B21&"|"&"CENTRO CUSTO - "&C21&"|"&I21&"|"&G21&"|"&#REF!&"|"&J21&"|"&H21&"|"&K21&"|"&L21&"|" -> #REF! | O21: =IF(M21=0,0,IF(E21="SEGURO DE VIDA EM GRUPO","31201003","31201005")) -> 31201005
... A42: 101 | B42: UNIMED ITUVERAVA | C42: 55030 | E42: UNIMED ITUVERAVA | F42: 546.96 | K42: ="|"&"PAGTO DOC - "&E42&"|"&"PLANO DE SAUDE - "&B42&"|"&"C CUSTO - "&LEFT(C42,5)&"|"&"TOTAL: "&F42&"|" -> |PAGTO DOC - UNIMED ITUVERAVA|PLANO DE SAUDE - UNIMED ITUVERAVA|C CUSTO - 55030|TOTAL: 546,96| | M42: =SUM(F42:L42) -> 546.96 | N42: ="|"&"PAGTO DOC - "&F42&"|"&"DESP - "&B42&"|"&"CENTRO CUSTO - "&C42&"|"&I42&"|"&G42&"|"&#REF!&"|"&J42&"|"&H42&"|"&K42&"|"&L42&"|" -> #REF! | O42: =IF(M42=0,0,IF(E42="SEGURO DE VIDA EM GRUPO","31201003","31201005")) -> 31201005
A43: 101 | B43: UNIMED ITUVERAVA | C43: 21012 | E43: UNIMED ITUVERAVA | F43: 229.3 | K43: ="|"&"PAGTO DOC - "&E43&"|"&"PLANO DE SAUDE - "&B43&"|"&"C CUSTO - "&LEFT(C43,5)&"|"&"TOTAL: "&F43&"|" -> |PAGTO DOC - UNIMED ITUVERAVA|PLANO DE SAUDE - UNIMED ITUVERAVA|C CUSTO - 21012|TOTAL: 229,3| | M43: =SUM(F43:L43) -> 229.3 | N43: ="|"&"PAGTO DOC - "&F43&"|"&"DESP - "&B43&"|"&"CENTRO CUSTO - "&C43&"|"&I43&"|"&G43&"|"&#REF!&"|"&J43&"|"&H43&"|"&K43&"|"&L43&"|" -> #REF! | O43: =IF(M43=0,0,IF(E43="SEGURO DE VIDA EM GRUPO","31201003","31201005")) -> 31201005
A44: 101 | B44: UNIMED ITUVERAVA | C44: 31090 | E44: UNIMED ITUVERAVA | F44: 546.96 | K44: ="|"&"PAGTO DOC - "&E44&"|"&"PLANO DE SAUDE - "&B44&"|"&"C CUSTO - "&LEFT(C44,5)&"|"&"TOTAL: "&F44&"|" -> |PAGTO DOC - UNIMED ITUVERAVA|PLANO DE SAUDE - UNIMED ITUVERAVA|C CUSTO - 31090|TOTAL: 546,96| | M44: =SUM(F44:L44) -> 546.96 | N44: ="|"&"PAGTO DOC - "&F44&"|"&"DESP - "&B44&"|"&"CENTRO CUSTO - "&C44&"|"&I44&"|"&G44&"|"&#REF!&"|"&J44&"|"&H44&"|"&K44&"|"&L44&"|" -> #REF! | O44: =IF(M44=0,0,IF(E44="SEGURO DE VIDA EM GRUPO","31201003","31201005")) -> 31201005
A45: 101 | B45: UNIMED ITUVERAVA | C45: 13016 | E45: UNIMED ITUVERAVA | F45: 229.3 | K45: ="|"&"PAGTO DOC - "&E45&"|"&"PLANO DE SAUDE - "&B45&"|"&"C CUSTO - "&LEFT(C45,5)&"|"&"TOTAL: "&F45&"|" -> |PAGTO DOC - UNIMED ITUVERAVA|PLANO DE SAUDE - UNIMED ITUVERAVA|C CUSTO - 13016|TOTAL: 229,3| | M45: =SUM(F45:L45) -> 229.3 | N45: ="|"&"PAGTO DOC - "&F45&"|"&"DESP - "&B45&"|"&"CENTRO CUSTO - "&C45&"|"&I45&"|"&G45&"|"&#REF!&"|"&J45&"|"&H45&"|"&K45&"|"&L45&"|" -> #REF! | O45: =IF(M45=0,0,IF(E45="SEGURO DE VIDA EM GRUPO","31201003","31201005")) -> 31201005
A46: 101 | B46: UNIMED ITUVERAVA | C46: 33050 | E46: UNIMED ITUVERAVA | F46: 546.96 | K46: ="|"&"PAGTO DOC - "&E46&"|"&"PLANO DE SAUDE - "&B46&"|"&"C CUSTO - "&LEFT(C46,5)&"|"&"TOTAL: "&F46&"|" -> |PAGTO DOC - UNIMED ITUVERAVA|PLANO DE SAUDE - UNIMED ITUVERAVA|C CUSTO - 33050|TOTAL: 546,96| | M46: =SUM(F46:L46) -> 546.96 | N46: ="|"&"PAGTO DOC - "&F46&"|"&"DESP - "&B46&"|"&"CENTRO CUSTO - "&C46&"|"&I46&"|"&G46&"|"&#REF!&"|"&J46&"|"&H46&"|"&K46&"|"&L46&"|" -> #REF! | O46: =IF(M46=0,0,IF(E46="SEGURO DE VIDA EM GRUPO","31201003","31201005")) -> 31201005
A47: 101 | B47: UNIMED ITUVERAVA | C47: 21011 | E47: UNIMED ITUVERAVA | F47: 229.3 | K47: ="|"&"PAGTO DOC - "&E47&"|"&"PLANO DE SAUDE - "&B47&"|"&"C CUSTO - "&LEFT(C47,5)&"|"&"TOTAL: "&F47&"|" -> |PAGTO DOC - UNIMED ITUVERAVA|PLANO DE SAUDE - UNIMED ITUVERAVA|C CUSTO - 21011|TOTAL: 229,3| | M47: =SUM(F47:L47) -> 229.3 | N47: ="|"&"PAGTO DOC - "&F47&"|"&"DESP - "&B47&"|"&"CENTRO CUSTO - "&C47&"|"&I47&"|"&G47&"|"&#REF!&"|"&J47&"|"&H47&"|"&K47&"|"&L47&"|" -> #REF! | O47: =IF(M47=0,0,IF(E47="SEGURO DE VIDA EM GRUPO","31201003","31201005")) -> 31201005
A48: 101 | B48: SEGURO DE VIDA EM GRUPO | C48: 11011 | E48: SEGURO DE VIDA EM GRUPO | F48: 74.15 | K48: ="|"&"PAGTO DOC - "&E48&"|"&"PLANO DE SAUDE - "&B48&"|"&"C CUSTO - "&LEFT(C48,5)&"|"&"TOTAL: "&F48&"|" -> |PAGTO DOC - SEGURO DE VIDA EM GRUPO|PLANO DE SAUDE - SEGURO DE VIDA EM GRUPO|C CUSTO - 11011|TOTAL: 74,15| | M48: =SUM(F48:L48) -> 74.15 | N48: ="|"&"PAGTO DOC - "&F48&"|"&"DESP - "&B48&"|"&"CENTRO CUSTO - "&C48&"|"&I48&"|"&G48&"|"&#REF!&"|"&J48&"|"&H48&"|"&K48&"|"&L48&"|" -> #REF! | O48: =IF(M48=0,0,IF(E48="SEGURO DE VIDA EM GRUPO","31201003","31201005")) -> 31201003
A49: 101 | B49: SEGURO DE VIDA EM GRUPO | C49: 13013 | E49: SEGURO DE VIDA EM GRUPO | F49: 8.04 | K49: ="|"&"PAGTO DOC - "&E49&"|"&"PLANO DE SAUDE - "&B49&"|"&"C CUSTO - "&LEFT(C49,5)&"|"&"TOTAL: "&F49&"|" -> |PAGTO DOC - SEGURO DE VIDA EM GRUPO|PLANO DE SAUDE - SEGURO DE VIDA EM GRUPO|C CUSTO - 13013|TOTAL: 8,04| | M49: =SUM(F49:L49) -> 8.04 | N49: ="|"&"PAGTO DOC - "&F49&"|"&"DESP - "&B49&"|"&"CENTRO CUSTO - "&C49&"|"&I49&"|"&G49&"|"&#REF!&"|"&J49&"|"&H49&"|"&K49&"|"&L49&"|" -> #REF! | O49: =IF(M49=0,0,IF(E49="SEGURO DE VIDA EM GRUPO","31201003","31201005")) -> 31201003
A50: 101 | B50: SEGURO DE VIDA EM GRUPO | C50: 13014 | E50: SEGURO DE VIDA EM GRUPO | F50: 74.15 | K50: ="|"&"PAGTO DOC - "&E50&"|"&"PLANO DE SAUDE - "&B50&"|"&"C CUSTO - "&LEFT(C50,5)&"|"&"TOTAL: "&F50&"|" -> |PAGTO DOC - SEGURO DE VIDA EM GRUPO|PLANO DE SAUDE - SEGURO DE VIDA EM GRUPO|C CUSTO - 13014|TOTAL: 74,15| | M50: =SUM(F50:L50) -> 74.15 | N50: ="|"&"PAGTO DOC - "&F50&"|"&"DESP - "&B50&"|"&"CENTRO CUSTO - "&C50&"|"&I50&"|"&G50&"|"&#REF!&"|"&J50&"|"&H50&"|"&K50&"|"&L50&"|" -> #REF! | O50: =IF(M50=0,0,IF(E50="SEGURO DE VIDA EM GRUPO","31201003","31201005")) -> 31201003
A51: 101 | B51: SEGURO DE VIDA EM GRUPO | C51: 14050 | E51: SEGURO DE VIDA EM GRUPO | F51: 72.36 | K51: ="|"&"PAGTO DOC - "&E51&"|"&"PLANO DE SAUDE - "&B51&"|"&"C CUSTO - "&LEFT(C51,5)&"|"&"TOTAL: "&F51&"|" -> |PAGTO DOC - SEGURO DE VIDA EM GRUPO|PLANO DE SAUDE - SEGURO DE VIDA EM GRUPO|C CUSTO - 14050|TOTAL: 72,36| | M51: =SUM(F51:L51) -> 72.36 | N51: ="|"&"PAGTO DOC - "&F51&"|"&"DESP - "&B51&"|"&"CENTRO CUSTO - "&C51&"|"&I51&"|"&G51&"|"&#REF!&"|"&J51&"|"&H51&"|"&K51&"|"&L51&"|" -> #REF! | O51: =IF(M51=0,0,IF(E51="SEGURO DE VIDA EM GRUPO","31201003","31201005")) -> 31201003
A52: 101 | B52: SEGURO DE VIDA EM GRUPO | C52: 14051 | E52: SEGURO DE VIDA EM GRUPO | F52: 201 | K52: ="|"&"PAGTO DOC - "&E52&"|"&"PLANO DE SAUDE - "&B52&"|"&"C CUSTO - "&LEFT(C52,5)&"|"&"TOTAL: "&F52&"|" -> |PAGTO DOC - SEGURO DE VIDA EM GRUPO|PLANO DE SAUDE - SEGURO DE VIDA EM GRUPO|C CUSTO - 14051|TOTAL: 201| | M52: =SUM(F52:L52) -> 201 | N52: ="|"&"PAGTO DOC - "&F52&"|"&"DESP - "&B52&"|"&"CENTRO CUSTO - "&C52&"|"&I52&"|"&G52&"|"&#REF!&"|"&J52&"|"&H52&"|"&K52&"|"&L52&"|" -> #REF! | O52: =IF(M52=0,0,IF(E52="SEGURO DE VIDA EM GRUPO","31201003","31201005")) -> 31201003
A53: 101 | B53: SEGURO DE VIDA EM GRUPO | C53: 14052 | E53: SEGURO DE VIDA EM GRUPO | F53: 88.44 | K53: ="|"&"PAGTO DOC - "&E53&"|"&"PLANO DE SAUDE - "&B53&"|"&"C CUSTO - "&LEFT(C53,5)&"|"&"TOTAL: "&F53&"|" -> |PAGTO DOC - SEGURO DE VIDA EM GRUPO|PLANO DE SAUDE - SEGURO DE VIDA EM GRUPO|C CUSTO - 14052|TOTAL: 88,44| | M53: =SUM(F53:L53) -> 88.44 | N53: ="|"&"PAGTO DOC - "&F53&"|"&"DESP - "&B53&"|"&"CENTRO CUSTO - "&C53&"|"&I53&"|"&G53&"|"&#REF!&"|"&J53&"|"&H53&"|"&K53&"|"&L53&"|" -> #REF! | O53: =IF(M53=0,0,IF(E53="SEGURO DE VIDA EM GRUPO","31201003","31201005")) -> 31201003
A54: 101 | B54: SEGURO DE VIDA EM GRUPO | C54: 14054 | E54: SEGURO DE VIDA EM GRUPO | F54: 90.23 | K54: ="|"&"PAGTO DOC - "&E54&"|"&"PLANO DE SAUDE - "&B54&"|"&"C CUSTO - "&LEFT(C54,5)&"|"&"TOTAL: "&F54&"|" -> |PAGTO DOC - SEGURO DE VIDA EM GRUPO|PLANO DE SAUDE - SEGURO DE VIDA EM GRUPO|C CUSTO - 14054|TOTAL: 90,23| | M54: =SUM(F54:L54) -> 90.23 | N54: ="|"&"PAGTO DOC - "&F54&"|"&"DESP - "&B54&"|"&"CENTRO CUSTO - "&C54&"|"&I54&"|"&G54&"|"&#REF!&"|"&J54&"|"&H54&"|"&K54&"|"&L54&"|" -> #REF! | O54: =IF(M54=0,0,IF(E54="SEGURO DE VIDA EM GRUPO","31201003","31201005")) -> 31201003
... A65: 101 | B65: SEGURO DE VIDA EM GRUPO | C65: 31200 | E65: SEGURO DE VIDA EM GRUPO | F65: 8.04 | K65: ="|"&"PAGTO DOC - "&E65&"|"&"PLANO DE SAUDE - "&B65&"|"&"C CUSTO - "&LEFT(C65,5)&"|"&"TOTAL: "&F65&"|" -> |PAGTO DOC - SEGURO DE VIDA EM GRUPO|PLANO DE SAUDE - SEGURO DE VIDA EM GRUPO|C CUSTO - 31200|TOTAL: 8,04| | M65: =SUM(F65:L65) -> 8.04 | N65: ="|"&"PAGTO DOC - "&F65&"|"&"DESP - "&B65&"|"&"CENTRO CUSTO - "&C65&"|"&I65&"|"&G65&"|"&#REF!&"|"&J65&"|"&H65&"|"&K65&"|"&L65&"|" -> #REF! | O65: =IF(M65=0,0,IF(E65="SEGURO DE VIDA EM GRUPO","31201003","31201005")) -> 31201003
A66: 101 | B66: SEGURO DE VIDA EM GRUPO | C66: 11011 | E66: SEGURO DE VIDA EM GRUPO | F66: 230.49 | K66: ="|"&"PAGTO DOC - "&E66&"|"&"PLANO DE SAUDE - "&B66&"|"&"C CUSTO - "&LEFT(C66,5)&"|"&"TOTAL: "&F66&"|" -> |PAGTO DOC - SEGURO DE VIDA EM GRUPO|PLANO DE SAUDE - SEGURO DE VIDA EM GRUPO|C CUSTO - 11011|TOTAL: 230,49| | M66: =SUM(F66:L66) -> 230.49 | N66: ="|"&"PAGTO DOC - "&F66&"|"&"DESP - "&B66&"|"&"CENTRO CUSTO - "&C66&"|"&I66&"|"&G66&"|"&#REF!&"|"&J66&"|"&H66&"|"&K66&"|"&L66&"|" -> #REF! | O66: =IF(M66=0,0,IF(E66="SEGURO DE VIDA EM GRUPO","31201003","31201005")) -> 31201003
A67: 101 | B67: SEGURO DE VIDA EM GRUPO | C67: 11012 | E67: SEGURO DE VIDA EM GRUPO | F67: 90.23 | K67: ="|"&"PAGTO DOC - "&E67&"|"&"PLANO DE SAUDE - "&B67&"|"&"C CUSTO - "&LEFT(C67,5)&"|"&"TOTAL: "&F67&"|" -> |PAGTO DOC - SEGURO DE VIDA EM GRUPO|PLANO DE SAUDE - SEGURO DE VIDA EM GRUPO|C CUSTO - 11012|TOTAL: 90,23| | M67: =SUM(F67:L67) -> 90.23 | N67: ="|"&"PAGTO DOC - "&F67&"|"&"DESP - "&B67&"|"&"CENTRO CUSTO - "&C67&"|"&I67&"|"&G67&"|"&#REF!&"|"&J67&"|"&H67&"|"&K67&"|"&L67&"|" -> #REF! | O67: =IF(M67=0,0,IF(E67="SEGURO DE VIDA EM GRUPO","31201003","31201005")) -> 31201003
A68: 101 | B68: SEGURO DE VIDA EM GRUPO | C68: 11013 | E68: SEGURO DE VIDA EM GRUPO | F68: 74.15 | K68: ="|"&"PAGTO DOC - "&E68&"|"&"PLANO DE SAUDE - "&B68&"|"&"C CUSTO - "&LEFT(C68,5)&"|"&"TOTAL: "&F68&"|" -> |PAGTO DOC - SEGURO DE VIDA EM GRUPO|PLANO DE SAUDE - SEGURO DE VIDA EM GRUPO|C CUSTO - 11013|TOTAL: 74,15| | M68: =SUM(F68:L68) -> 74.15 | N68: ="|"&"PAGTO DOC - "&F68&"|"&"DESP - "&B68&"|"&"CENTRO CUSTO - "&C68&"|"&I68&"|"&G68&"|"&#REF!&"|"&J68&"|"&H68&"|"&K68&"|"&L68&"|" -> #REF! | O68: =IF(M68=0,0,IF(E68="SEGURO DE VIDA EM GRUPO","31201003","31201005")) -> 31201003
A69: 101 | B69: SEGURO DE VIDA EM GRUPO | C69: 13011 | E69: SEGURO DE VIDA EM GRUPO | F69: 64.32 | K69: ="|"&"PAGTO DOC - "&E69&"|"&"PLANO DE SAUDE - "&B69&"|"&"C CUSTO - "&LEFT(C69,5)&"|"&"TOTAL: "&F69&"|" -> |PAGTO DOC - SEGURO DE VIDA EM GRUPO|PLANO DE SAUDE - SEGURO DE VIDA EM GRUPO|C CUSTO - 13011|TOTAL: 64,32| | M69: =SUM(F69:L69) -> 64.32 | N69: ="|"&"PAGTO DOC - "&F69&"|"&"DESP - "&B69&"|"&"CENTRO CUSTO - "&C69&"|"&I69&"|"&G69&"|"&#REF!&"|"&J69&"|"&H69&"|"&K69&"|"&L69&"|" -> #REF! | O69: =IF(M69=0,0,IF(E69="SEGURO DE VIDA EM GRUPO","31201003","31201005")) -> 31201003
A70: 101 | B70: SEGURO DE VIDA EM GRUPO | C70: 13012 | E70: SEGURO DE VIDA EM GRUPO | F70: 16.08 | K70: ="|"&"PAGTO DOC - "&E70&"|"&"PLANO DE SAUDE - "&B70&"|"&"C CUSTO - "&LEFT(C70,5)&"|"&"TOTAL: "&F70&"|" -> |PAGTO DOC - SEGURO DE VIDA EM GRUPO|PLANO DE SAUDE - SEGURO DE VIDA EM GRUPO|C CUSTO - 13012|TOTAL: 16,08| | M70: =SUM(F70:L70) -> 16.08 | N70: ="|"&"PAGTO DOC - "&F70&"|"&"DESP - "&B70&"|"&"CENTRO CUSTO - "&C70&"|"&I70&"|"&G70&"|"&#REF!&"|"&J70&"|"&H70&"|"&K70&"|"&L70&"|" -> #REF! | O70: =IF(M70=0,0,IF(E70="SEGURO DE VIDA EM GRUPO","31201003","31201005")) -> 31201003
A71: 101 | B71: SEGURO DE VIDA EM GRUPO | C71: 13013 | E71: SEGURO DE VIDA EM GRUPO | F71: 128.33 | K71: ="|"&"PAGTO DOC - "&E71&"|"&"PLANO DE SAUDE - "&B71&"|"&"C CUSTO - "&LEFT(C71,5)&"|"&"TOTAL: "&F71&"|" -> |PAGTO DOC - SEGURO DE VIDA EM GRUPO|PLANO DE SAUDE - SEGURO DE VIDA EM GRUPO|C CUSTO - 13013|TOTAL: 128,33| | M71: =SUM(F71:L71) -> 128.33 | N71: ="|"&"PAGTO DOC - "&F71&"|"&"DESP - "&B71&"|"&"CENTRO CUSTO - "&C71&"|"&I71&"|"&G71&"|"&#REF!&"|"&J71&"|"&H71&"|"&K71&"|"&L71&"|" -> #REF! | O71: =IF(M71=0,0,IF(E71="SEGURO DE VIDA EM GRUPO","31201003","31201005")) -> 31201003
...

Sheet Consolidado
F1: =SUM(F3:F243) -> 291294.1
A2: ESTAB | B2: TIPO DE DESP: | C2: CCUSTO | D2: DATA | E2: Nº DOC | F2: MENSAL | G2: EXAME | H2: DESCON | I2: REPRES | J2: INSCRI | K2: X | L2: Z | M2: TOTAL | N2: CONTA
A3: 101 | B3: UNIMED ITUVERAVA | C3: 13021 | E3: UNIMED ITUVERAVA | F3: 546.96 | M3: =F3 -> 546.96 | N3: =IF(B3="SEGURO DE VIDA EM GRUPO","31201003","31201005") -> 31201005
A4: 101 | B4: UNIMED ITUVERAVA | C4: 14051 | E4: UNIMED ITUVERAVA | F4: 2161.26 | M4: =F4 -> 2161.26 | N4: =IF(B4="SEGURO DE VIDA EM GRUPO","31201003","31201005") -> 31201005
A5: 101 | B5: UNIMED ITUVERAVA | C5: 14058 | E5: UNIMED ITUVERAVA | F5: 2014.32 | M5: =F5 -> 2014.32 | N5: =IF(B5="SEGURO DE VIDA EM GRUPO","31201003","31201005") -> 31201005
A6: 101 | B6: UNIMED ITUVERAVA | C6: 31060 | E6: UNIMED ITUVERAVA | F6: 546.96 | M6: =F6 -> 546.96 | N6: =IF(B6="SEGURO DE VIDA EM GRUPO","31201003","31201005") -> 31201005
A7: 101 | B7: UNIMED ITUVERAVA | C7: 31070 | E7: UNIMED ITUVERAVA | F7: 546.96 | M7: =F7 -> 546.96 | N7: =IF(B7="SEGURO DE VIDA EM GRUPO","31201003","31201005") -> 31201005
A8: 101 | B8: UNIMED ITUVERAVA | C8: 31114 | E8: UNIMED ITUVERAVA | F8: 2417.14 | M8: =F8 -> 2417.14 | N8: =IF(B8="SEGURO DE VIDA EM GRUPO","31201003","31201005") -> 31201005
A9: 101 | B9: UNIMED ITUVERAVA | C9: 11012 | E9: UNIMED ITUVERAVA | F9: 1093.92 | M9: =F9 -> 1093.92 | N9: =IF(B9="SEGURO DE VIDA EM GRUPO","31201003","31201005") -> 31201005
A10: 101 | B10: UNIMED ITUVERAVA | C10: 13011 | E10: UNIMED ITUVERAVA | F10: 1323.22 | M10: =F10 -> 1323.22 | N10: =IF(B10="SEGURO DE VIDA EM GRUPO","31201003","31201005") -> 31201005
A11: 101 | B11: UNIMED ITUVERAVA | C11: 13012 | E11: UNIMED ITUVERAVA | F11: 1005.56 | M11: =F11 -> 1005.56 | N11: =IF(B11="SEGURO DE VIDA EM GRUPO","31201003","31201005") -> 31201005
A12: 101 | B12: UNIMED ITUVERAVA | C12: 13013 | E12: UNIMED ITUVERAVA | F12: 8067.44 | M12: =F12 -> 8067.44 | N12: =IF(B12="SEGURO DE VIDA EM GRUPO","31201003","31201005") -> 31201005
A13: 101 | B13: UNIMED ITUVERAVA | C13: 13014 | E13: UNIMED ITUVERAVA | F13: 2187.84 | M13: =F13 -> 2187.84 | N13: =IF(B13="SEGURO DE VIDA EM GRUPO","31201003","31201005") -> 31201005
A14: 101 | B14: UNIMED ITUVERAVA | C14: 13016 | E14: UNIMED ITUVERAVA | F14: 1464.16 | M14: =F14 -> 1464.16 | N14: =IF(B14="SEGURO DE VIDA EM GRUPO","31201003","31201005") -> 31201005
A15: 101 | B15: UNIMED ITUVERAVA | C15: 13017 | E15: UNIMED ITUVERAVA | F15: 1640.88 | M15: =F15 -> 1640.88 | N15: =IF(B15="SEGURO DE VIDA EM GRUPO","31201003","31201005") -> 31201005
A16: 101 | B16: UNIMED ITUVERAVA | C16: 13018 | E16: UNIMED ITUVERAVA | F16: 1005.56 | M16: =F16 -> 1005.56 | N16: =IF(B16="SEGURO DE VIDA EM GRUPO","31201003","31201005") -> 31201005
A17: 101 | B17: UNIMED ITUVERAVA | C17: 13019 | E17: UNIMED ITUVERAVA | F17: 776.26 | M17: =F17 -> 776.26 | N17: =IF(B17="SEGURO DE VIDA EM GRUPO","31201003","31201005") -> 31201005
A18: 101 | B18: UNIMED ITUVERAVA | C18: 13021 | E18: UNIMED ITUVERAVA | F18: 2646.44 | M18: =F18 -> 2646.44 | N18: =IF(B18="SEGURO DE VIDA EM GRUPO","31201003","31201005") -> 31201005
A19: 101 | B19: UNIMED ITUVERAVA | C19: 14012 | E19: UNIMED ITUVERAVA | F19: 1870.18 | M19: =F19 -> 1870.18 | N19: =IF(B19="SEGURO DE VIDA EM GRUPO","31201003","31201005") -> 31201005
A20: 101 | B20: UNIMED ITUVERAVA | C20: 14051 | E20: UNIMED ITUVERAVA | F20: 2707.02 | M20: =F20 -> 2707.02 | N20: =IF(B20="SEGURO DE VIDA EM GRUPO","31201003","31201005") -> 31201005
... A41: 101 | B41: UNIMED ITUVERAVA | C41: 55030 | E41: UNIMED ITUVERAVA | F41: 546.96 | M41: =F41 -> 546.96 | N41: =IF(B41="SEGURO DE VIDA EM GRUPO","31201003","31201005") -> 31201005
A42: 101 | B42: UNIMED ITUVERAVA | C42: 21012 | E42: UNIMED ITUVERAVA | F42: 229.3 | M42: =F42 -> 229.3 | N42: =IF(B42="SEGURO DE VIDA EM GRUPO","31201003","31201005") -> 31201005
A43: 101 | B43: UNIMED ITUVERAVA | C43: 31090 | E43: UNIMED ITUVERAVA | F43: 546.96 | M43: =F43 -> 546.96 | N43: =IF(B43="SEGURO DE VIDA EM GRUPO","31201003","31201005") -> 31201005
A44: 101 | B44: UNIMED ITUVERAVA | C44: 13016 | E44: UNIMED ITUVERAVA | F44: 229.3 | M44: =F44 -> 229.3 | N44: =IF(B44="SEGURO DE VIDA EM GRUPO","31201003","31201005") -> 31201005
A45: 101 | B45: UNIMED ITUVERAVA | C45: 33050 | E45: UNIMED ITUVERAVA | F45: 546.96 | M45: =F45 -> 546.96 | N45: =IF(B45="SEGURO DE VIDA EM GRUPO","31201003","31201005") -> 31201005
A46: 101 | B46: UNIMED ITUVERAVA | C46: 21011 | E46: UNIMED ITUVERAVA | F46: 229.3 | M46: =F46 -> 229.3 | N46: =IF(B46="SEGURO DE VIDA EM GRUPO","31201003","31201005") -> 31201005
A48: 101 | B48: SEGURO DE VIDA EM GRUPO | C48: 11011 | E48: SEGURO DE VIDA EM GRUPO | F48: 74.15 | M48: =F48 -> 74.15 | N48: =IF(B48="SEGURO DE VIDA EM GRUPO","31201003","31201005") -> 31201003
A49: 101 | B49: SEGURO DE VIDA EM GRUPO | C49: 13013 | E49: SEGURO DE VIDA EM GRUPO | F49: 8.04 | M49: =F49 -> 8.04 | N49: =IF(B49="SEGURO DE VIDA EM GRUPO","31201003","31201005") -> 31201003
A50: 101 | B50: SEGURO DE VIDA EM GRUPO | C50: 13014 | E50: SEGURO DE VIDA EM GRUPO | F50: 74.15 | M50: =F50 -> 74.15 | N50: =IF(B50="SEGURO DE VIDA EM GRUPO","31201003","31201005") -> 31201003
A51: 101 | B51: SEGURO DE VIDA EM GRUPO | C51: 14050 | E51: SEGURO DE VIDA EM GRUPO | F51: 72.36 | M51: =F51 -> 72.36 | N51: =IF(B51="SEGURO DE VIDA EM GRUPO","31201003","31201005") -> 31201003
A52: 101 | B52: SEGURO DE VIDA EM GRUPO | C52: 14051 | E52: SEGURO DE VIDA EM GRUPO | F52: 201 | M52: =F52 -> 201 | N52: =IF(B52="SEGURO DE VIDA EM GRUPO","31201003","31201005") -> 31201003
A53: 101 | B53: SEGURO DE VIDA EM GRUPO | C53: 14052 | E53: SEGURO DE VIDA EM GRUPO | F53: 88.44 | M53: =F53 -> 88.44 | N53: =IF(B53="SEGURO DE VIDA EM GRUPO","31201003","31201005") -> 31201003
A54: 101 | B54: SEGURO DE VIDA EM GRUPO | C54: 14054 | E54: SEGURO DE VIDA EM GRUPO | F54: 90.23 | M54: =F54 -> 90.23 | N54: =IF(B54="SEGURO DE VIDA EM GRUPO","31201003","31201005") -> 31201003
... A65: 101 | B65: SEGURO DE VIDA EM GRUPO | C65: 31200 | E65: SEGURO DE VIDA EM GRUPO | F65: 8.04 | M65: =F65 -> 8.04 | N65: =IF(B65="SEGURO DE VIDA EM GRUPO","31201003","31201005") -> 31201003
A66: 101 | B66: SEGURO DE VIDA EM GRUPO | C66: 11011 | E66: SEGURO DE VIDA EM GRUPO | F66: 230.49 | M66: =F66 -> 230.49 | N66: =IF(B66="SEGURO DE VIDA EM GRUPO","31201003","31201005") -> 31201003
A67: 101 | B67: SEGURO DE VIDA EM GRUPO | C67: 11012 | E67: SEGURO DE VIDA EM GRUPO | F67: 90.23 | M67: =F67 -> 90.23 | N67: =IF(B67="SEGURO DE VIDA EM GRUPO","31201003","31201005") -> 31201003
A68: 101 | B68: SEGURO DE VIDA EM GRUPO | C68: 11013 | E68: SEGURO DE VIDA EM GRUPO | F68: 74.15 | M68: =F68 -> 74.15 | N68: =IF(B68="SEGURO DE VIDA EM GRUPO","31201003","31201005") -> 31201003
A69: 101 | B69: SEGURO DE VIDA EM GRUPO | C69: 13011 | E69: SEGURO DE VIDA EM GRUPO | F69: 64.32 | M69: =F69 -> 64.32 | N69: =IF(B69="SEGURO DE VIDA EM GRUPO","31201003","31201005") -> 31201003
A70: 101 | B70: SEGURO DE VIDA EM GRUPO | C70: 13012 | E70: SEGURO DE VIDA EM GRUPO | F70: 16.08 | M70: =F70 -> 16.08 | N70: =IF(B70="SEGURO DE VIDA EM GRUPO","31201003","31201005") -> 31201003
A71: 101 | B71: SEGURO DE VIDA EM GRUPO | C71: 13013 | E71: SEGURO DE VIDA EM GRUPO | F71: 128.33 | M71: =F71 -> 128.33 | N71: =IF(B71="SEGURO DE VIDA EM GRUPO","31201003","31201005") -> 31201003
...

Sheet SAUDE AGO2026
A1: REAL | B1: 1 | C1: 1 | D1: FGL | E1: 546.96 | F1: GERAL | G1: 46265 | H1: 1 | I1: CR | K1: 101 | L1: PLANO MÊS 08/2026 | M1: 1 | N1: 31550109 | O1: |PAGTO DOC - UNIMED ITUVERAVA|PLANO DE SAUDE - UNIMED ITUVERAVA|C CUSTO - 13021|TOTAL: 546,96| | Q1: NAO | R1: GERAL | S1: 13021 | T1: 19000 | U1: 31201005 | V1: 2 | W1: ='PLANO DE SAÚDE'!C4 -> 13021
A2: REAL | B2: =B1+2 -> 3 | C2: 1 | D2: FGL | E2: 2161.26 | F2: GERAL | G2: 46265 | H2: 1 | I2: CR | K2: 101 | L2: PLANO MÊS 08/2026 | M2: 1 | N2: 31550109 | O2: |PAGTO DOC - UNIMED ITUVERAVA|PLANO DE SAUDE - UNIMED ITUVERAVA|C CUSTO - 14051|TOTAL: 2161,26| | Q2: NAO | R2: GERAL | S2: 14051 | T2: 19000 | U2: 31201005 | V2: =V1+2 -> 4 | W2: ='PLANO DE SAÚDE'!C5 -> 14051
A3: REAL | B3: =B2+2 -> 5 | C3: 1 | D3: FGL | E3: 2014.32 | F3: GERAL | G3: 46265 | H3: 1 | I3: CR | K3: 101 | L3: PLANO MÊS 08/2026 | M3: 1 | N3: 31550109 | O3: |PAGTO DOC - UNIMED ITUVERAVA|PLANO DE SAUDE - UNIMED ITUVERAVA|C CUSTO - 14058|TOTAL: 2014,32| | Q3: NAO | R3: GERAL | S3: 14058 | T3: 19000 | U3: 31201005 | V3: =V2+2 -> 6 | W3: ='PLANO DE SAÚDE'!C6 -> 14058
A4: REAL | B4: =B3+2 -> 7 | C4: 1 | D4: FGL | E4: 546.96 | F4: GERAL | G4: 46265 | H4: 1 | I4: CR | K4: 101 | L4: PLANO MÊS 08/2026 | M4: 1 | N4: 31550109 | O4: |PAGTO DOC - UNIMED ITUVERAVA|PLANO DE SAUDE - UNIMED ITUVERAVA|C CUSTO - 31060|TOTAL: 546,96| | Q4: NAO | R4: GERAL | S4: 31060 | T4: 19000 | U4: 31201005 | V4: =V3+2 -> 8 | W4: ='PLANO DE SAÚDE'!C7 -> 31060
A5: REAL | B5: =B4+2 -> 9 | C5: 1 | D5: FGL | E5: 546.96 | F5: GERAL | G5: 46265 | H5: 1 | I5: CR | K5: 101 | L5: PLANO MÊS 08/2026 | M5: 1 | N5: 31550109 | O5: |PAGTO DOC - UNIMED ITUVERAVA|PLANO DE SAUDE - UNIMED ITUVERAVA|C CUSTO - 31070|TOTAL: 546,96| | Q5: NAO | R5: GERAL | S5: 31070 | T5: 19000 | U5: 31201005 | V5: =V4+2 -> 10 | W5: ='PLANO DE SAÚDE'!C8 -> 31070
A6: REAL | B6: =B5+2 -> 11 | C6: 1 | D6: FGL | E6: 2417.14 | F6: GERAL | G6: 46265 | H6: 1 | I6: CR | K6: 101 | L6: PLANO MÊS 08/2026 | M6: 1 | N6: 31550109 | O6: |PAGTO DOC - UNIMED ITUVERAVA|PLANO DE SAUDE - UNIMED ITUVERAVA|C CUSTO - 31114|TOTAL: 2417,14| | Q6: NAO | R6: GERAL | S6: 31114 | T6: 19000 | U6: 31201005 | V6: =V5+2 -> 12 | W6: ='PLANO DE SAÚDE'!C9 -> 31114
A7: REAL | B7: =B6+2 -> 13 | C7: 1 | D7: FGL | E7: 1093.92 | F7: GERAL | G7: 46265 | H7: 1 | I7: CR | K7: 101 | L7: PLANO MÊS 08/2026 | M7: 1 | N7: 31550109 | O7: |PAGTO DOC - UNIMED ITUVERAVA|PLANO DE SAUDE - UNIMED ITUVERAVA|C CUSTO - 11012|TOTAL: 1093,92| | Q7: NAO | R7: GERAL | S7: 11012 | T7: 19000 | U7: 31201005 | V7: =V6+2 -> 14 | W7: ='PLANO DE SAÚDE'!C10 -> 11012
A8: REAL | B8: =B7+2 -> 15 | C8: 1 | D8: FGL | E8: 1323.22 | F8: GERAL | G8: 46265 | H8: 1 | I8: CR | K8: 101 | L8: PLANO MÊS 08/2026 | M8: 1 | N8: 31550109 | O8: |PAGTO DOC - UNIMED ITUVERAVA|PLANO DE SAUDE - UNIMED ITUVERAVA|C CUSTO - 13011|TOTAL: 1323,22| | Q8: NAO | R8: GERAL | S8: 13011 | T8: 19000 | U8: 31201005 | V8: =V7+2 -> 16 | W8: ='PLANO DE SAÚDE'!C11 -> 13011
A9: REAL | B9: =B8+2 -> 17 | C9: 1 | D9: FGL | E9: 1005.56 | F9: GERAL | G9: 46265 | H9: 1 | I9: CR | K9: 101 | L9: PLANO MÊS 08/2026 | M9: 1 | N9: 31550109 | O9: |PAGTO DOC - UNIMED ITUVERAVA|PLANO DE SAUDE - UNIMED ITUVERAVA|C CUSTO - 13012|TOTAL: 1005,56| | Q9: NAO | R9: GERAL | S9: 13012 | T9: 19000 | U9: 31201005 | V9: =V8+2 -> 18 | W9: ='PLANO DE SAÚDE'!C12 -> 13012
A10: REAL | B10: =B9+2 -> 19 | C10: 1 | D10: FGL | E10: 8067.44 | F10: GERAL | G10: 46265 | H10: 1 | I10: CR | K10: 101 | L10: PLANO MÊS 08/2026 | M10: 1 | N10: 31550109 | O10: |PAGTO DOC - UNIMED ITUVERAVA|PLANO DE SAUDE - UNIMED ITUVERAVA|C CUSTO - 13013|TOTAL: 8067,44| | Q10: NAO | R10: GERAL | S10: 13013 | T10: 19000 | U10: 31201005 | V10: =V9+2 -> 20 | W10: ='PLANO DE SAÚDE'!C13 -> 13013
A11: REAL | B11: =B10+2 -> 21 | C11: 1 | D11: FGL | E11: 2187.84 | F11: GERAL | G11: 46265 | H11: 1 | I11: CR | K11: 101 | L11: PLANO MÊS 08/2026 | M11: 1 | N11: 31550109 | O11: |PAGTO DOC - UNIMED ITUVERAVA|PLANO DE SAUDE - UNIMED ITUVERAVA|C CUSTO - 13014|TOTAL: 2187,84| | Q11: NAO | R11: GERAL | S11: 13014 | T11: 19000 | U11: 31201005 | V11: =V10+2 -> 22 | W11: ='PLANO DE SAÚDE'!C14 -> 13014
A12: REAL | B12: =B11+2 -> 23 | C12: 1 | D12: FGL | E12: 1464.16 | F12: GERAL | G12: 46265 | H12: 1 | I12: CR | K12: 101 | L12: PLANO MÊS 08/2026 | M12: 1 | N12: 31550109 | O12: |PAGTO DOC - UNIMED ITUVERAVA|PLANO DE SAUDE - UNIMED ITUVERAVA|C CUSTO - 13016|TOTAL: 1464,16| | Q12: NAO | R12: GERAL | S12: 13016 | T12: 19000 | U12: 31201005 | V12: =V11+2 -> 24 | W12: ='PLANO DE SAÚDE'!C15 -> 13016
A13: REAL | B13: =B12+2 -> 25 | C13: 1 | D13: FGL | E13: 1640.88 | F13: GERAL | G13: 46265 | H13: 1 | I13: CR | K13: 101 | L13: PLANO MÊS 08/2026 | M13: 1 | N13: 31550109 | O13: |PAGTO DOC - UNIMED ITUVERAVA|PLANO DE SAUDE - UNIMED ITUVERAVA|C CUSTO - 13017|TOTAL: 1640,88| | Q13: NAO | R13: GERAL | S13: 13017 | T13: 19000 | U13: 31201005 | V13: =V12+2 -> 26 | W13: ='PLANO DE SAÚDE'!C16 -> 13017
A14: REAL | B14: =B13+2 -> 27 | C14: 1 | D14: FGL | E14: 1005.56 | F14: GERAL | G14: 46265 | H14: 1 | I14: CR | K14: 101 | L14: PLANO MÊS 08/2026 | M14: 1 | N14: 31550109 | O14: |PAGTO DOC - UNIMED ITUVERAVA|PLANO DE SAUDE - UNIMED ITUVERAVA|C CUSTO - 13018|TOTAL: 1005,56| | Q14: NAO | R14: GERAL | S14: 13018 | T14: 19000 | U14: 31201005 | V14: =V13+2 -> 28 | W14: ='PLANO DE SAÚDE'!C17 -> 13018
A15: REAL | B15: =B14+2 -> 29 | C15: 1 | D15: FGL | E15: 776.26 | F15: GERAL | G15: 46265 | H15: 1 | I15: CR | K15: 101 | L15: PLANO MÊS 08/2026 | M15: 1 | N15: 31550109 | O15: |PAGTO DOC - UNIMED ITUVERAVA|PLANO DE SAUDE - UNIMED ITUVERAVA|C CUSTO - 13019|TOTAL: 776,26| | Q15: NAO | R15: GERAL | S15: 13019 | T15: 19000 | U15: 31201005 | V15: =V14+2 -> 30 | W15: ='PLANO DE SAÚDE'!C18 -> 13019
A16: REAL | B16: =B15+2 -> 31 | C16: 1 | D16: FGL | E16: 2646.44 | F16: GERAL | G16: 46265 | H16: 1 | I16: CR | K16: 101 | L16: PLANO MÊS 08/2026 | M16: 1 | N16: 31550109 | O16: |PAGTO DOC - UNIMED ITUVERAVA|PLANO DE SAUDE - UNIMED ITUVERAVA|C CUSTO - 13021|TOTAL: 2646,44| | Q16: NAO | R16: GERAL | S16: 13021 | T16: 19000 | U16: 31201005 | V16: =V15+2 -> 32 | W16: ='PLANO DE SAÚDE'!C19 -> 13021
A17: REAL | B17: =B16+2 -> 33 | C17: 1 | D17: FGL | E17: 1870.18 | F17: GERAL | G17: 46265 | H17: 1 | I17: CR | K17: 101 | L17: PLANO MÊS 08/2026 | M17: 1 | N17: 31550109 | O17: |PAGTO DOC - UNIMED ITUVERAVA|PLANO DE SAUDE - UNIMED ITUVERAVA|C CUSTO - 14012|TOTAL: 1870,18| | Q17: NAO | R17: GERAL | S17: 14012 | T17: 19000 | U17: 31201005 | V17: =V16+2 -> 34 | W17: ='PLANO DE SAÚDE'!C20 -> 14012
A18: REAL | B18: =B17+2 -> 35 | C18: 1 | D18: FGL | E18: 2707.02 | F18: GERAL | G18: 46265 | H18: 1 | I18: CR | K18: 101 | L18: PLANO MÊS 08/2026 | M18: 1 | N18: 31550109 | O18: |PAGTO DOC - UNIMED ITUVERAVA|PLANO DE SAUDE - UNIMED ITUVERAVA|C CUSTO - 14051|TOTAL: 2707,02| | Q18: NAO | R18: GERAL | S18: 14051 | T18: 19000 | U18: 31201005 | V18: =V17+2 -> 36 | W18: ='PLANO DE SAÚDE'!C21 -> 14051
... A39: REAL | B39: =B38+2 -> 77 | C39: 1 | D39: FGL | E39: 546.96 | F39: GERAL | G39: 46265 | H39: 1 | I39: CR | K39: 101 | L39: PLANO MÊS 08/2026 | M39: 1 | N39: 31550109 | O39: |PAGTO DOC - UNIMED ITUVERAVA|PLANO DE SAUDE - UNIMED ITUVERAVA|C CUSTO - 55030|TOTAL: 546,96| | Q39: NAO | R39: GERAL | S39: 55030 | T39: 19000 | U39: 31201005 | V39: =V38+2 -> 78 | W39: ='PLANO DE SAÚDE'!C42 -> 55030
A40: REAL | B40: =B39+2 -> 79 | C40: 1 | D40: FGL | E40: 229.3 | F40: GERAL | G40: 46265 | H40: 1 | I40: CR | K40: 101 | L40: PLANO MÊS 08/2026 | M40: 1 | N40: 31550109 | O40: |PAGTO DOC - UNIMED ITUVERAVA|PLANO DE SAUDE - UNIMED ITUVERAVA|C CUSTO - 21012|TOTAL: 229,3| | Q40: NAO | R40: GERAL | S40: 21012 | T40: 19000 | U40: 31201005 | V40: =V39+2 -> 80 | W40: ='PLANO DE SAÚDE'!C43 -> 21012
A41: REAL | B41: =B40+2 -> 81 | C41: 1 | D41: FGL | E41: 546.96 | F41: GERAL | G41: 46265 | H41: 1 | I41: CR | K41: 101 | L41: PLANO MÊS 08/2026 | M41: 1 | N41: 31550109 | O41: |PAGTO DOC - UNIMED ITUVERAVA|PLANO DE SAUDE - UNIMED ITUVERAVA|C CUSTO - 31090|TOTAL: 546,96| | Q41: NAO | R41: GERAL | S41: 31090 | T41: 19000 | U41: 31201005 | V41: =V40+2 -> 82 | W41: ='PLANO DE SAÚDE'!C44 -> 31090
A42: REAL | B42: =B41+2 -> 83 | C42: 1 | D42: FGL | E42: 229.3 | F42: GERAL | G42: 46265 | H42: 1 | I42: CR | K42: 101 | L42: PLANO MÊS 08/2026 | M42: 1 | N42: 31550109 | O42: |PAGTO DOC - UNIMED ITUVERAVA|PLANO DE SAUDE - UNIMED ITUVERAVA|C CUSTO - 13016|TOTAL: 229,3| | Q42: NAO | R42: GERAL | S42: 13016 | T42: 19000 | U42: 31201005 | V42: =V41+2 -> 84 | W42: ='PLANO DE SAÚDE'!C45 -> 13016
A43: REAL | B43: =B42+2 -> 85 | C43: 1 | D43: FGL | E43: 546.96 | F43: GERAL | G43: 46265 | H43: 1 | I43: CR | K43: 101 | L43: PLANO MÊS 08/2026 | M43: 1 | N43: 31550109 | O43: |PAGTO DOC - UNIMED ITUVERAVA|PLANO DE SAUDE - UNIMED ITUVERAVA|C CUSTO - 33050|TOTAL: 546,96| | Q43: NAO | R43: GERAL | S43: 33050 | T43: 19000 | U43: 31201005 | V43: =V42+2 -> 86 | W43: ='PLANO DE SAÚDE'!C46 -> 33050
A44: REAL | B44: =B43+2 -> 87 | C44: 1 | D44: FGL | E44: 229.3 | F44: GERAL | G44: 46265 | H44: 1 | I44: CR | K44: 101 | L44: PLANO MÊS 08/2026 | M44: 1 | N44: 31550109 | O44: |PAGTO DOC - UNIMED ITUVERAVA|PLANO DE SAUDE - UNIMED ITUVERAVA|C CUSTO - 21011|TOTAL: 229,3| | Q44: NAO | R44: GERAL | S44: 21011 | T44: 19000 | U44: 31201005 | V44: =V43+2 -> 88 | W44: ='PLANO DE SAÚDE'!C47 -> 21011
A45: REAL | B45: =B44+2 -> 89 | C45: 1 | D45: FGL | E45: 74.15 | F45: GERAL | G45: 46265 | H45: 1 | I45: CR | K45: 101 | L45: PLANO MÊS 08/2026 | M45: 1 | N45: 31550109 | O45: |PAGTO DOC - SEGURO DE VIDA EM GRUPO|PLANO DE SAUDE - SEGURO DE VIDA EM GRUPO|C CUSTO - 11011|TOTAL: 74,15| | Q45: NAO | R45: GERAL | S45: 11011 | T45: 19000 | U45: 31201003 | V45: =V44+2 -> 90 | W45: ='PLANO DE SAÚDE'!#REF! -> #REF!
A46: REAL | B46: =B45+2 -> 91 | C46: 1 | D46: FGL | E46: 8.04 | F46: GERAL | G46: 46265 | H46: 1 | I46: CR | K46: 101 | L46: PLANO MÊS 08/2026 | M46: 1 | N46: 31550109 | O46: |PAGTO DOC - SEGURO DE VIDA EM GRUPO|PLANO DE SAUDE - SEGURO DE VIDA EM GRUPO|C CUSTO - 13013|TOTAL: 8,04| | Q46: NAO | R46: GERAL | S46: 13013 | T46: 19000 | U46: 31201003 | V46: =V45+2 -> 92 | W46: ='PLANO DE SAÚDE'!#REF! -> #REF!
A47: REAL | B47: =B46+2 -> 93 | C47: 1 | D47: FGL | E47: 74.15 | F47: GERAL | G47: 46265 | H47: 1 | I47: CR | K47: 101 | L47: PLANO MÊS 08/2026 | M47: 1 | N47: 31550109 | O47: |PAGTO DOC - SEGURO DE VIDA EM GRUPO|PLANO DE SAUDE - SEGURO DE VIDA EM GRUPO|C CUSTO - 13014|TOTAL: 74,15| | Q47: NAO | R47: GERAL | S47: 13014 | T47: 19000 | U47: 31201003 | V47: =V46+2 -> 94 | W47: ='PLANO DE SAÚDE'!C48 -> 11011
A48: REAL | B48: =B47+2 -> 95 | C48: 1 | D48: FGL | E48: 72.36 | F48: GERAL | G48: 46265 | H48: 1 | I48: CR | K48: 101 | L48: PLANO MÊS 08/2026 | M48: 1 | N48: 31550109 | O48: |PAGTO DOC - SEGURO DE VIDA EM GRUPO|PLANO DE SAUDE - SEGURO DE VIDA EM GRUPO|C CUSTO - 14050|TOTAL: 72,36| | Q48: NAO | R48: GERAL | S48: 14050 | T48: 19000 | U48: 31201003 | V48: =V47+2 -> 96 | W48: ='PLANO DE SAÚDE'!C49 -> 13013
A49: REAL | B49: =B48+2 -> 97 | C49: 1 | D49: FGL | E49: 201 | F49: GERAL | G49: 46265 | H49: 1 | I49: CR | K49: 101 | L49: PLANO MÊS 08/2026 | M49: 1 | N49: 31550109 | O49: |PAGTO DOC - SEGURO DE VIDA EM GRUPO|PLANO DE SAUDE - SEGURO DE VIDA EM GRUPO|C CUSTO - 14051|TOTAL: 201| | Q49: NAO | R49: GERAL | S49: 14051 | T49: 19000 | U49: 31201003 | V49: =V48+2 -> 98 | W49: ='PLANO DE SAÚDE'!C50 -> 13014
A50: REAL | B50: =B49+2 -> 99 | C50: 1 | D50: FGL | E50: 88.44 | F50: GERAL | G50: 46265 | H50: 1 | I50: CR | K50: 101 | L50: PLANO MÊS 08/2026 | M50: 1 | N50: 31550109 | O50: |PAGTO DOC - SEGURO DE VIDA EM GRUPO|PLANO DE SAUDE - SEGURO DE VIDA EM GRUPO|C CUSTO - 14052|TOTAL: 88,44| | Q50: NAO | R50: GERAL | S50: 14052 | T50: 19000 | U50: 31201003 | V50: =V49+2 -> 100 | W50: ='PLANO DE SAÚDE'!C51 -> 14050
A51: REAL | B51: =B50+2 -> 101 | C51: 1 | D51: FGL | E51: 90.23 | F51: GERAL | G51: 46265 | H51: 1 | I51: CR | K51: 101 | L51: PLANO MÊS 08/2026 | M51: 1 | N51: 31550109 | O51: |PAGTO DOC - SEGURO DE VIDA EM GRUPO|PLANO DE SAUDE - SEGURO DE VIDA EM GRUPO|C CUSTO - 14054|TOTAL: 90,23| | Q51: NAO | R51: GERAL | S51: 14054 | T51: 19000 | U51: 31201003 | V51: =V50+2 -> 102 | W51: ='PLANO DE SAÚDE'!C52 -> 14051
A52: REAL | B52: =B51+2 -> 103 | C52: 1 | D52: FGL | E52: 64.32 | F52: GERAL | G52: 46265 | H52: 1 | I52: CR | K52: 101 | L52: PLANO MÊS 08/2026 | M52: 1 | N52: 31550109 | O52: |PAGTO DOC - SEGURO DE VIDA EM GRUPO|PLANO DE SAUDE - SEGURO DE VIDA EM GRUPO|C CUSTO - 14056|TOTAL: 64,32| | Q52: NAO | R52: GERAL | S52: 14056 | T52: 19000 | U52: 31201003 | V52: =V51+2 -> 104 | W52: ='PLANO DE SAÚDE'!C53 -> 14052
A53: REAL | B53: =B52+2 -> 105 | C53: 1 | D53: FGL | E53: 209.04 | F53: GERAL | G53: 46265 | H53: 1 | I53: CR | K53: 101 | L53: PLANO MÊS 08/2026 | M53: 1 | N53: 31550109 | O53: |PAGTO DOC - SEGURO DE VIDA EM GRUPO|PLANO DE SAUDE - SEGURO DE VIDA EM GRUPO|C CUSTO - 14058|TOTAL: 209,04| | Q53: NAO | R53: GERAL | S53: 14058 | T53: 19000 | U53: 31201003 | V53: =V52+2 -> 106 | W53: ='PLANO DE SAÚDE'!C54 -> 14054
A54: REAL | B54: =B53+2 -> 107 | C54: 1 | D54: FGL | E54: 8.04 | F54: GERAL | G54: 46265 | H54: 1 | I54: CR | K54: 101 | L54: PLANO MÊS 08/2026 | M54: 1 | N54: 31550109 | O54: |PAGTO DOC - SEGURO DE VIDA EM GRUPO|PLANO DE SAUDE - SEGURO DE VIDA EM GRUPO|C CUSTO - 14062|TOTAL: 8,04| | Q54: NAO | R54: GERAL | S54: 14062 | T54: 19000 | U54: 31201003 | V54: =V53+2 -> 108 | W54: ='PLANO DE SAÚDE'!C55 -> 14056
A55: REAL | B55: =B54+2 -> 109 | C55: 1 | D55: FGL | E55: 74.15 | F55: GERAL | G55: 46265 | H55: 1 | I55: CR | K55: 101 | L55: PLANO MÊS 08/2026 | M55: 1 | N55: 31550109 | O55: |PAGTO DOC - SEGURO DE VIDA EM GRUPO|PLANO DE SAUDE - SEGURO DE VIDA EM GRUPO|C CUSTO - 15012|TOTAL: 74,15| | Q55: NAO | R55: GERAL | S55: 15012 | T55: 19000 | U55: 31201003 | V55: =V54+2 -> 110 | W55: ='PLANO DE SAÚDE'!C56 -> 14058
A56: REAL | B56: =B55+2 -> 111 | C56: 1 | D56: FGL | E56: 24.12 | F56: GERAL | G56: 46265 | H56: 1 | I56: CR | K56: 101 | L56: PLANO MÊS 08/2026 | M56: 1 | N56: 31550109 | O56: |PAGTO DOC - SEGURO DE VIDA EM GRUPO|PLANO DE SAUDE - SEGURO DE VIDA EM GRUPO|C CUSTO - 15050|TOTAL: 24,12| | Q56: NAO | R56: GERAL | S56: 15050 | T56: 19000 | U56: 31201003 | V56: =V55+2 -> 112 | W56: ='PLANO DE SAÚDE'!C57 -> 14062
A57: REAL | B57: =B56+2 -> 113 | C57: 1 | D57: FGL | E57: 16.08 | F57: GERAL | G57: 46265 | H57: 1 | I57: CR | K57: 101 | L57: PLANO MÊS 08/2026 | M57: 1 | N57: 31550109 | O57: |PAGTO DOC - SEGURO DE VIDA EM GRUPO|PLANO DE SAUDE - SEGURO DE VIDA EM GRUPO|C CUSTO - 15051|TOTAL: 16,08| | Q57: NAO | R57: GERAL | S57: 15051 | T57: 19000 | U57: 31201003 | V57: =V56+2 -> 114 | W57: ='PLANO DE SAÚDE'!C58 -> 15012
A58: REAL | B58: =B57+2 -> 115 | C58: 1 | D58: FGL | E58: 48.24 | F58: GERAL | G58: 46265 | H58: 1 | I58: CR | K58: 101 | L58: PLANO MÊS 08/2026 | M58: 1 | N58: 31550109 | O58: |PAGTO DOC - SEGURO DE VIDA EM GRUPO|PLANO DE SAUDE - SEGURO DE VIDA EM GRUPO|C CUSTO - 31060|TOTAL: 48,24| | Q58: NAO | R58: GERAL | S58: 31060 | T58: 19000 | U58: 31201003 | V58: =V57+2 -> 116 | W58: ='PLANO DE SAÚDE'!C59 -> 15050
... A62: REAL | B62: =B61+2 -> 123 | C62: 1 | D62: FGL | E62: 8.04 | F62: GERAL | G62: 46265 | H62: 1 | I62: CR | K62: 101 | L62: PLANO MÊS 08/2026 | M62: 1 | N62: 31550109 | O62: |PAGTO DOC - SEGURO DE VIDA EM GRUPO|PLANO DE SAUDE - SEGURO DE VIDA EM GRUPO|C CUSTO - 31200|TOTAL: 8,04| | Q62: NAO | R62: GERAL | S62: 31200 | T62: 19000 | U62: 31201003 | V62: =V61+2 -> 124 | W62: ='PLANO DE SAÚDE'!C63 -> 31111
A63: REAL | B63: =B62+2 -> 125 | C63: 1 | D63: FGL | E63: 230.49 | F63: GERAL | G63: 46265 | H63: 1 | I63: CR | K63: 101 | L63: PLANO MÊS 08/2026 | M63: 1 | N63: 31550109 | O63: |PAGTO DOC - SEGURO DE VIDA EM GRUPO|PLANO DE SAUDE - SEGURO DE VIDA EM GRUPO|C CUSTO - 11011|TOTAL: 230,49| | Q63: NAO | R63: GERAL | S63: 11011 | T63: 19000 | U63: 31201003 | V63: =V62+2 -> 126 | W63: ='PLANO DE SAÚDE'!C64 -> 31114
...

Sheet SAUDE
A1: REAL 1 1FGL 7.159,75GERAL 31/01/2023 1CRFISCAL 101PLANO MÊS 01/2023 1 31550109 | B1: |PAGTO DOC - SEGURO SAÚDE|PLANO DE SAUDE - SEGURO SAÚDE|C CUSTO - 14113|TOTAL: 7159,75| NAOGERAL 141131900031201005 2
A2: REAL 3 1FGL 4.868,63GERAL 31/01/2023 1CRFISCAL 101PLANO MÊS 01/2023 1 31550109 | B2: |PAGTO DOC - SEGURO SAÚDE|PLANO DE SAUDE - SEGURO SAÚDE|C CUSTO - 14119|TOTAL: 4868,63| NAOGERAL 141191900031201005 4
A3: REAL 5 1FGL 4.295,85GERAL 31/01/2023 1CRFISCAL 101PLANO MÊS 01/2023 1 31550109 | B3: |PAGTO DOC - SEGURO SAÚDE|PLANO DE SAUDE - SEGURO SAÚDE|C CUSTO - 14111|TOTAL: 4295,85| NAOGERAL 141111900031201005 6
A4: REAL 7 1FGL 2.291,12GERAL 31/01/2023 1CRFISCAL 101PLANO MÊS 01/2023 1 31550109 | B4: |PAGTO DOC - SEGURO SAÚDE|PLANO DE SAUDE - SEGURO SAÚDE|C CUSTO - 14056|TOTAL: 2291,12| NAOGERAL 140561900031201005 8
A5: REAL 9 1FGL 5.155,02GERAL 31/01/2023 1CRFISCAL 101PLANO MÊS 01/2023 1 31550109 | B5: |PAGTO DOC - SEGURO SAÚDE|PLANO DE SAUDE - SEGURO SAÚDE|C CUSTO - 14116|TOTAL: 5155,02| NAOGERAL 141161900031201005 10
A6: REAL 11 1FGL 23.140,13GERAL 31/01/2023 1CRFISCAL 101PLANO MÊS 01/2023 1 31550109 | B6: |PAGTO DOC - SEGURO SAÚDE|PLANO DE SAUDE - SEGURO SAÚDE|C CUSTO - 11011|TOTAL: 23140,13| NAOGERAL 110111900031201005 12
A7: REAL 13 1FGL 859,17GERAL 31/01/2023 1CRFISCAL 101PLANO MÊS 01/2023 1 31550109 | B7: |PAGTO DOC - SEGURO SAÚDE|PLANO DE SAUDE - SEGURO SAÚDE|C CUSTO - 14112|TOTAL: 859,17| NAOGERAL 141121900031201005 14
A8: REAL 15 1FGL 7.230,19GERAL 31/01/2023 1CRFISCAL 101PLANO MÊS 01/2023 1 31550109 | B8: |PAGTO DOC - SEGURO SAÚDE|PLANO DE SAUDE - SEGURO SAÚDE|C CUSTO - 14051|TOTAL: 7230,19| NAOGERAL 140511900031201005 16
A9: REAL 17 1FGL 3.150,29GERAL 31/01/2023 1CRFISCAL 101PLANO MÊS 01/2023 1 31550109 | B9: |PAGTO DOC - SEGURO SAÚDE|PLANO DE SAUDE - SEGURO SAÚDE|C CUSTO - 14120|TOTAL: 3150,29| NAOGERAL 141201900031201005 18
A10: REAL 19 1FGL 1.145,56GERAL 31/01/2023 1CRFISCAL 101PLANO MÊS 01/2023 1 31550109 | B10: |PAGTO DOC - SEGURO SAÚDE|PLANO DE SAUDE - SEGURO SAÚDE|C CUSTO - 14059|TOTAL: 1145,56| NAOGERAL 140591900031201005 20
A11: REAL 21 1FGL 6.943,80GERAL 31/01/2023 1CRFISCAL 101PLANO MÊS 01/2023 1 31550109 | B11: |PAGTO DOC - SEGURO SAÚDE|PLANO DE SAUDE - SEGURO SAÚDE|C CUSTO - 11012|TOTAL: 6943,8| NAOGERAL 110121900031201005 22
A12: REAL 23 1FGL 859,17GERAL 31/01/2023 1CRFISCAL 101PLANO MÊS 01/2023 1 31550109 | B12: |PAGTO DOC - SEGURO SAÚDE|PLANO DE SAUDE - SEGURO SAÚDE|C CUSTO - 14060|TOTAL: 859,17| NAOGERAL 140601900031201005 24
... A131: REAL 261 1FGL 7,00GERAL 31/01/2023 1CRFISCAL 101PLANO MÊS 01/2023 1 31550109 | B131: |PAGTO DOC - SEGURO DE VIDA EM GRUPO|PLANO DE SAUDE - SEGURO DE VIDA EM GRUPO|C CUSTO - 14110|TOTAL: 7| NAOGERAL 141101900031201003 262

Sheet RAZAO
A1: Data | B1: Plano Contas | C1: Conta Contábil | D1: Transação | E1: Referência | F1: Fornecedor | G1: Nome Abreviado | H1: Estab. | I1: Plano de Centro de Custo | J1: CCusto | K1: Esp | L1: Série | M1: Título | N1: Parcela | O1: Portador | P1: Número Cheque | Q1: Valor DB | R1: Valor CR | S1: Contra Partida | T1: Histor
Q7: =SUM(Q2:Q6) -> 0
G11: APB + CE0403 | H11: PLANILHA
F12: 101 | G12: =SUMIFS($Q$2:$Q$9,$H$2:$H$9,F12)-SUMIFS($R$2:$R$9,$H$2:$H$9,F12)+SUMIFS($P$21:$P$38,$D$21:$D$38,F12) -> 264756.28 | H12: =SUMIFS(Consolidado!F:F,Consolidado!A:A,RAZAO!F12) -> 264756.28 | I12: =G12-H12 -> 0
F13: 104 | G13: =SUMIFS($Q$2:$Q$9,$H$2:$H$9,F13)-SUMIFS($R$2:$R$9,$H$2:$H$9,F13)+SUMIFS($P$21:$P$38,$D$21:$D$38,F13) -> 2513.52 | H13: =SUMIFS(Consolidado!F:F,Consolidado!A:A,RAZAO!F13) -> 2513.52 | I13: =G13-H13 -> 0
F14: 106 | G14: =SUMIFS($Q$2:$Q$9,$H$2:$H$9,F14)-SUMIFS($R$2:$R$9,$H$2:$H$9,F14)+SUMIFS($P$21:$P$38,$D$21:$D$38,F14) -> 24024.3 | H14: =SUMIFS(Consolidado!F:F,Consolidado!A:A,RAZAO!F14) -> 24024.3 | I14: =G14-H14 -> 0
A20: Conta | B20: Centro Custo | C20: UNeg | D20: Estab | E20: Data Trans | F20: Depósito | G20: Espécie | H20: Série | I20: Documento | J20: Emitente | K20: Num Ordem | L20: Item | M20: UM | N20: Qtde | O20: Total | P20: Débito | Q20: Crédito | R20: Narrativa: | S20: Descrição Item | T20: Nome Abrev
A21: 3.1.55.01.09 | C21: 1 | D21: 101 | E21: 46245 | F21: DIR | G21: NFE | H21: 1 | I21: 0012692 | J21: 50337 | K21: 0.00 | L21: DD-014 | M21: UN | N21: 1 | P21: 5501.2 | Q21: 0 | R21: NOSSO PAGAMENTO REFERENTE AO PLANO DE ASSISTENCIA ODONTOLOGICA DOS COLABORADORES DE ITUVERAVA - ESTABELECIMENTO 101 | DOCUMENTO ENVIADO POR E-MAIL PELA AMANDA (RH) NO DIA 05/08/2026. | S21: GASTOS COM CONVENIO MEDICO | T21: UNIDENT
A22: 3.1.55.01.09 | C22: 1 | D22: 101 | E22: 46246 | F22: DIR | G22: NFE | H22: BOL | I22: 6313020 | J22: 53525 | K22: 0.00 | L22: DD-404 | M22: UN | N22: 1 | P22: 3099.15 | Q22: 0 | R22: NOSSO PAGAMENTO REFERENTE AO PLANO DE SAÚDE UNIMED ODONTO DOS COLABORADORES DA MATRIZ SANTA MARIA | DOCUMENTO ENVIADO POR E-MAIL POR AMANDA TEIXEIRA (RH) NO DIA 11/08/2026 | S22: GASTOS COM CONVENIO MEDICO | T22: UNIMED ODONT
A23: 3.1.55.01.09 | C23: 1 | D23: 101 | E23: 46247 | F23: DIR | G23: NFE | H23: FAT | I23: 0000499 | J23: 50426 | K23: 0.00 | L23: DD-404 | M23: UN | N23: 1 | P23: 76224.17 | Q23: 0 | R23: PAGAMENTO MENSAL DE CONVÊNIO MÉDICO COLETIVO EMPRESARIAL DA COMPETÊNCIA 08/2026 | CONFORME DEMONSTRATIVO DE FATURA N° 2600005172.01/000499 MODALIDADE/CONTRATO N° 000041 | DOCUMENTO ENVIADO POR AMANDA TEIXEIRA VIA E-MAIL NO DIA 11/08/2026 | NÚMERO DE ORIGEM DESTE LANÇAMENTO: NUMERO DA FATURA ENVIADA. | S23: FATURA | CONVÊNIO MÉDICO | T23: UNIMED ITUV
A24: 3.1.55.01.09 | C24: 1 | D24: 101 | E24: 46247 | F24: DIR | G24: NFE | H24: FAT | I24: 0000500 | J24: 50426 | K24: 0.00 | L24: DD-404 | M24: UN | N24: 1 | P24: 24426.27 | Q24: 0 | R24: PAGAMENTO MENSAL DE CONVÊNIO MÉDICO COLETIVO EMPRESARIAL DA COMPETÊNCIA 08/2026 | CONFORME DEMONSTRATIVO DE FATURA N° 2600005173.01/000500 MODALIDADE/CONTRATO N° 000048 | DOCUMENTO ENVIADO POR AMANDA TEIXEIRA VIA E-MAIL NO DIA 11/08/2026 | NÚMERO DE ORIGEM DESTE LANÇAMENTO: NUMERO DA FATURA ENVIADA. | S24: FATURA | CONVÊNIO MÉDICO | T24: UNIMED ITUV
A25: 3.1.55.01.09 | C25: 1 | D25: 101 | E25: 46247 | F25: DIR | G25: NFE | H25: FAT | I25: 0000501 | J25: 50426 | K25: 0.00 | L25: DD-404 | M25: UN | N25: 1 | P25: 5393.26 | Q25: 0 | R25: PAGAMENTO MENSAL DE CONVÊNIO MÉDICO COLETIVO EMPRESARIAL DA COMPETÊNCIA 08/2026 | CONFORME DEMONSTRATIVO DE FATURA N° 2600005174.01/000501 MODALIDADE/CONTRATO N° 000242 | DOCUMENTO ENVIADO POR AMANDA TEIXEIRA VIA E-MAIL NO DIA 11/08/2026 | NÚMERO DE ORIGEM DESTE LANÇAMENTO: NUMERO DA FATURA ENVIADA. | S25: FATURA | CONVÊNIO MÉDICO | T25: UNIMED ITUV
A26: 3.1.55.01.09 | C26: 1 | D26: 101 | E26: 46247 | F26: DIR | G26: NFE | H26: FAT | I26: 0000502 | J26: 50426 | K26: 0.00 | L26: DD-404 | M26: UN | N26: 1 | P26: 4868.28 | Q26: 0 | R26: PAGAMENTO MENSAL DE CONVÊNIO MÉDICO COLETIVO EMPRESARIAL DA COMPETÊNCIA 08/2026 | CONFORME DEMONSTRATIVO DE FATURA N° 2600005175.01/000502 MODALIDADE/CONTRATO N° 000271 | DOCUMENTO ENVIADO POR AMANDA TEIXEIRA VIA E-MAIL NO DIA 11/08/2026 | NÚMERO DE ORIGEM DESTE LANÇAMENTO: NUMERO DA FATURA ENVIADA. | S26: FATURA | CONVÊNIO MÉDICO | T26: UNIMED ITUV
A27: 3.1.55.01.09 | C27: 1 | D27: 101 | E27: 46247 | F27: DIR | G27: NFE | H27: FAT | I27: 5160060 | J27: 52915 | K27: 0.00 | L27: DD-404 | M27: UN | N27: 1 | P27: 15015.12 | Q27: 0 | R27: NOSSO PAGAMENTO MENSAL REFERENTE AO SEGURO UNIMED CORPORATIVO SENIOR APTO (FR - TREINAMENTO PROFISSIONAL LTDA) | CONFORME APÓLICE N° 8771499 AGENTE: 994, PERÍODO DE VIGÊNCIA: 01/08/2026 A 31/08/2026 | DOCUMENTO ENVIADO POR AMANDA TEIXEIRA VIA E-MAIL NO DIA 11/08/2026 | NUMERO DE ORIGEM DESTE LANÇAMENTO: NÚMERO DA FATURA RECEBIDA. | S27: FATURA | CONVÊNIO MÉDICO | T27: SEGUROS UNIM
A28: 3.1.55.01.09 | C28: 1 | D28: 101 | E28: 46247 | F28: DIR | G28: NFE | H28: FAT | I28: 5160061 | J28: 52915 | K28: 0.00 | L28: DD-404 | M28: UN | N28: 1 | P28: 12512.6 | Q28: 0 | R28: NOSSO PAGAMENTO MENSAL REFERENTE AO SEGURO UNIMED CORPORATIVO SENIOR APTO (UTILIHOUSE REPRESENTAÇAO DE UTILIDADES DOMESTICAS LTDA) | CONFORME APÓLICE N° 8771499 AGENTE: 994, PERÍODO DE VIGÊNCIA: 01/08/2026 A 31/08/2026 | DOCUMENTO ENVIADO POR AMANDA TEIXEIRA VIA E-MAIL NO DIA 11/08/2026 | NUMERO DE ORIGEM DESTE LANÇAMENTO: NÚMERO DA FATURA RECEBIDA. | S28: FATURA | CONVÊNIO MÉDICO | T28: SEGUROS UNIM
A29: 3.1.55.01.09 | C29: 1 | D29: 101 | E29: 46247 | F29: DIR | G29: NFE | H29: FAT | I29: 5160062 | J29: 52915 | K29: 0.00 | L29: DD-404 | M29: UN | N29: 1 | P29: 412.85 | Q29: 0 | R29: NOSSO PAGAMENTO MENSAL REFERENTE AO SEGURO UNIMED CORPORATIVO COMPACTO ENF (CARLOS ROBERTO REAL ORSATTI) | CONFORME APÓLICE N° 8771499 AGENTE: 994, PERÍODO DE VIGÊNCIA: 01/08/2026 A 31/08/2026 | DOCUMENTO ENVIADO POR AMANDA TEIXEIRA VIA E-MAIL NO DIA 11/08/2026 | NUMERO DE ORIGEM DESTE LANÇAMENTO: NÚMERO DA FATURA RECEBIDA. | S29: FATURA | CONVÊNIO MÉDICO | T29: SEGUROS UNIM
A30: 3.1.55.01.09 | C30: 1 | D30: 101 | E30: 46247 | F30: DIR | G30: NFE | H30: FAT | I30: 5160063 | J30: 52915 | K30: 0.00 | L30: DD-404 | M30: UN | N30: 1 | P30: 87028.96 | Q30: 0 | R30: NOSSO PAGAMENTO MENSAL REFERENTE AO SEGURO UNIMED CORPORATIVO COMPACTO ENF E CORPORATIVO SENIOR APTO (IND E COM SANTA MARIA LTDA) | CONFORME APÓLICE N° 8771499 AGENTE: 994, PERÍODO DE VIGÊNCIA: 01/08/2026 A 31/08/2026 | DOCUMENTO ENVIADO POR AMANDA TEIXEIRA VIA E-MAIL NO DIA 11/08/2026 | NUMERO DE ORIGEM DESTE LANÇAMENTO: NÚMERO DA FATURA RECEBIDA. | S30: FATURA | CONVÊNIO MÉDICO | T30: SEGUROS UNIM
A31: 3.1.55.01.09 | C31: 1 | D31: 101 | E31: 46247 | F31: DIR | G31: NFE | H31: FAT | I31: 5160064 | J31: 52915 | K31: 0.00 | L31: DD-404 | M31: UN | N31: 1 | P31: 25025.2 | Q31: 0 | R31: NOSSO PAGAMENTO MENSAL REFERENTE AO SEGURO UNIMED CORPORATIVO SENIOR APTO (BRANCO E ORSATTI - TREINAMENTO PROFISSIONAL LTDA) | CONFORME APÓLICE N° 8771499 AGENTE: 994, PERÍODO DE VIGÊNCIA: 01/08/2026 A 31/08/2026 | DOCUMENTO ENVIADO POR AMANDA TEIXEIRA VIA E-MAIL NO DIA 11/08/2026 | NUMERO DE ORIGEM DESTE LANÇAMENTO: NÚMERO DA FATURA RECEBIDA. | S31: FATURA | CONVÊNIO MÉDICO | T31: SEGUROS UNIM
A32: 3.1.55.01.09 | C32: 1 | D32: 101 | E32: 46254 | F32: DIR | G32: NFE | H32: 1 | I32: 1422187 | J32: 455354 | K32: 0.00 | L32: DD-014 | M32: UN | N32: 1 | P32: 5249.22 | Q32: 0 | R32: NOSSO PAGAMENTO REFERENTE AO SEGURO DE VIDA DOS COLABORADORES DA MATRIZ SANTA MARIA | COMPETÊNCIA 08/2026 | DOCUMENTO ENVIADO POR LINDOMAR GONÇALVES (RH) EM 17/08/2026 VIA E-MAIL | NÚMERO DE ORIGEM DESTE LANÇAMENTO: NÚMERO DO DOCUMENTO PRESENTE NO BOLETO (2601422187). | S32: FATURA | CONVÊNIO MÉDICO | T32: UNIMED SEG.
... A38: 3.1.55.01.09 | C38: 1 | D38: 106 | E38: 46247 | F38: DIR | G38: NFE | H38: 1 | I38: 1411484 | J38: 455354 | K38: 0.00 | L38: DD-014 | M38: UN | N38: 1 | P38: 643.2 | Q38: 0 | R38: NOSSO PAGAMENTO REFERENTE AO SEGURO DE VIDA DOS COLABORADORES DA FILIAL 106 SANTA MARIA | COMPETÊNCIA 08/2026 | DOCUMENTO ENVIADO POR LINDOMAR GONÇALVES (RH) EM 05/08/2026 VIA E-MAIL | NÚMERO DE ORIGEM DESTE LANÇAMENTO: NÚMERO DO DOCUMENTO PRESENTE NO BOLETO (2601411484). | S38: FATURA | CONVÊNIO MÉDICO | T38: UNIMED SEG.

Sheet Plan2

Sheet Plan4
